{
 "cells": [
  {
   "cell_type": "code",
   "execution_count": 1,
   "id": "a582c99e-39f9-4e31-aa03-77690a17a59b",
   "metadata": {},
   "outputs": [
    {
     "name": "stderr",
     "output_type": "stream",
     "text": [
      "\n",
      "A module that was compiled using NumPy 1.x cannot be run in\n",
      "NumPy 2.2.4 as it may crash. To support both 1.x and 2.x\n",
      "versions of NumPy, modules must be compiled with NumPy 2.0.\n",
      "Some module may need to rebuild instead e.g. with 'pybind11>=2.12'.\n",
      "\n",
      "If you are a user of the module, the easiest solution will be to\n",
      "downgrade to 'numpy<2' or try to upgrade the affected module.\n",
      "We expect that some modules will need time to support NumPy 2.\n",
      "\n",
      "Traceback (most recent call last):  File \"<frozen runpy>\", line 198, in _run_module_as_main\n",
      "  File \"<frozen runpy>\", line 88, in _run_code\n",
      "  File \"/home/codespace/.local/lib/python3.12/site-packages/ipykernel_launcher.py\", line 18, in <module>\n",
      "    app.launch_new_instance()\n",
      "  File \"/home/codespace/.local/lib/python3.12/site-packages/traitlets/config/application.py\", line 1075, in launch_instance\n",
      "    app.start()\n",
      "  File \"/home/codespace/.local/lib/python3.12/site-packages/ipykernel/kernelapp.py\", line 739, in start\n",
      "    self.io_loop.start()\n",
      "  File \"/home/codespace/.local/lib/python3.12/site-packages/tornado/platform/asyncio.py\", line 205, in start\n",
      "    self.asyncio_loop.run_forever()\n",
      "  File \"/home/codespace/anaconda3/lib/python3.12/asyncio/base_events.py\", line 641, in run_forever\n",
      "    self._run_once()\n",
      "  File \"/home/codespace/anaconda3/lib/python3.12/asyncio/base_events.py\", line 1986, in _run_once\n",
      "    handle._run()\n",
      "  File \"/home/codespace/anaconda3/lib/python3.12/asyncio/events.py\", line 88, in _run\n",
      "    self._context.run(self._callback, *self._args)\n",
      "  File \"/home/codespace/.local/lib/python3.12/site-packages/ipykernel/kernelbase.py\", line 545, in dispatch_queue\n",
      "    await self.process_one()\n",
      "  File \"/home/codespace/.local/lib/python3.12/site-packages/ipykernel/kernelbase.py\", line 534, in process_one\n",
      "    await dispatch(*args)\n",
      "  File \"/home/codespace/.local/lib/python3.12/site-packages/ipykernel/kernelbase.py\", line 437, in dispatch_shell\n",
      "    await result\n",
      "  File \"/home/codespace/.local/lib/python3.12/site-packages/ipykernel/ipkernel.py\", line 362, in execute_request\n",
      "    await super().execute_request(stream, ident, parent)\n",
      "  File \"/home/codespace/.local/lib/python3.12/site-packages/ipykernel/kernelbase.py\", line 778, in execute_request\n",
      "    reply_content = await reply_content\n",
      "  File \"/home/codespace/.local/lib/python3.12/site-packages/ipykernel/ipkernel.py\", line 449, in do_execute\n",
      "    res = shell.run_cell(\n",
      "  File \"/home/codespace/.local/lib/python3.12/site-packages/ipykernel/zmqshell.py\", line 549, in run_cell\n",
      "    return super().run_cell(*args, **kwargs)\n",
      "  File \"/home/codespace/.local/lib/python3.12/site-packages/IPython/core/interactiveshell.py\", line 3047, in run_cell\n",
      "    result = self._run_cell(\n",
      "  File \"/home/codespace/.local/lib/python3.12/site-packages/IPython/core/interactiveshell.py\", line 3102, in _run_cell\n",
      "    result = runner(coro)\n",
      "  File \"/home/codespace/.local/lib/python3.12/site-packages/IPython/core/async_helpers.py\", line 128, in _pseudo_sync_runner\n",
      "    coro.send(None)\n",
      "  File \"/home/codespace/.local/lib/python3.12/site-packages/IPython/core/interactiveshell.py\", line 3306, in run_cell_async\n",
      "    has_raised = await self.run_ast_nodes(code_ast.body, cell_name,\n",
      "  File \"/home/codespace/.local/lib/python3.12/site-packages/IPython/core/interactiveshell.py\", line 3489, in run_ast_nodes\n",
      "    if await self.run_code(code, result, async_=asy):\n",
      "  File \"/home/codespace/.local/lib/python3.12/site-packages/IPython/core/interactiveshell.py\", line 3549, in run_code\n",
      "    exec(code_obj, self.user_global_ns, self.user_ns)\n",
      "  File \"/tmp/ipykernel_24631/1375686775.py\", line 1, in <module>\n",
      "    import sklearn\n",
      "  File \"/home/codespace/.local/lib/python3.12/site-packages/sklearn/__init__.py\", line 73, in <module>\n",
      "    from .base import clone  # noqa: E402\n",
      "  File \"/home/codespace/.local/lib/python3.12/site-packages/sklearn/base.py\", line 19, in <module>\n",
      "    from .utils._estimator_html_repr import _HTMLDocumentationLinkMixin, estimator_html_repr\n",
      "  File \"/home/codespace/.local/lib/python3.12/site-packages/sklearn/utils/__init__.py\", line 15, in <module>\n",
      "    from ._chunking import gen_batches, gen_even_slices\n",
      "  File \"/home/codespace/.local/lib/python3.12/site-packages/sklearn/utils/_chunking.py\", line 11, in <module>\n",
      "    from ._param_validation import Interval, validate_params\n",
      "  File \"/home/codespace/.local/lib/python3.12/site-packages/sklearn/utils/_param_validation.py\", line 17, in <module>\n",
      "    from .validation import _is_arraylike_not_scalar\n",
      "  File \"/home/codespace/.local/lib/python3.12/site-packages/sklearn/utils/validation.py\", line 21, in <module>\n",
      "    from ..utils._array_api import _asarray_with_order, _is_numpy_namespace, get_namespace\n",
      "  File \"/home/codespace/.local/lib/python3.12/site-packages/sklearn/utils/_array_api.py\", line 17, in <module>\n",
      "    from .fixes import parse_version\n",
      "  File \"/home/codespace/.local/lib/python3.12/site-packages/sklearn/utils/fixes.py\", line 20, in <module>\n",
      "    import pandas as pd\n",
      "  File \"/home/codespace/.local/lib/python3.12/site-packages/pandas/__init__.py\", line 26, in <module>\n",
      "    from pandas.compat import (\n",
      "  File \"/home/codespace/.local/lib/python3.12/site-packages/pandas/compat/__init__.py\", line 27, in <module>\n",
      "    from pandas.compat.pyarrow import (\n",
      "  File \"/home/codespace/.local/lib/python3.12/site-packages/pandas/compat/pyarrow.py\", line 8, in <module>\n",
      "    import pyarrow as pa\n",
      "  File \"/home/codespace/anaconda3/lib/python3.12/site-packages/pyarrow/__init__.py\", line 65, in <module>\n",
      "    import pyarrow.lib as _lib\n"
     ]
    },
    {
     "ename": "ImportError",
     "evalue": "\nA module that was compiled using NumPy 1.x cannot be run in\nNumPy 2.2.4 as it may crash. To support both 1.x and 2.x\nversions of NumPy, modules must be compiled with NumPy 2.0.\nSome module may need to rebuild instead e.g. with 'pybind11>=2.12'.\n\nIf you are a user of the module, the easiest solution will be to\ndowngrade to 'numpy<2' or try to upgrade the affected module.\nWe expect that some modules will need time to support NumPy 2.\n\n",
     "output_type": "error",
     "traceback": [
      "\u001b[31m---------------------------------------------------------------------------\u001b[39m",
      "\u001b[31mImportError\u001b[39m                               Traceback (most recent call last)",
      "\u001b[36mFile \u001b[39m\u001b[32m~/.local/lib/python3.12/site-packages/numpy/core/_multiarray_umath.py:44\u001b[39m, in \u001b[36m__getattr__\u001b[39m\u001b[34m(attr_name)\u001b[39m\n\u001b[32m     39\u001b[39m     \u001b[38;5;66;03m# Also print the message (with traceback).  This is because old versions\u001b[39;00m\n\u001b[32m     40\u001b[39m     \u001b[38;5;66;03m# of NumPy unfortunately set up the import to replace (and hide) the\u001b[39;00m\n\u001b[32m     41\u001b[39m     \u001b[38;5;66;03m# error.  The traceback shouldn't be needed, but e.g. pytest plugins\u001b[39;00m\n\u001b[32m     42\u001b[39m     \u001b[38;5;66;03m# seem to swallow it and we should be failing anyway...\u001b[39;00m\n\u001b[32m     43\u001b[39m     sys.stderr.write(msg + tb_msg)\n\u001b[32m---> \u001b[39m\u001b[32m44\u001b[39m     \u001b[38;5;28;01mraise\u001b[39;00m \u001b[38;5;167;01mImportError\u001b[39;00m(msg)\n\u001b[32m     46\u001b[39m ret = \u001b[38;5;28mgetattr\u001b[39m(_multiarray_umath, attr_name, \u001b[38;5;28;01mNone\u001b[39;00m)\n\u001b[32m     47\u001b[39m \u001b[38;5;28;01mif\u001b[39;00m ret \u001b[38;5;129;01mis\u001b[39;00m \u001b[38;5;28;01mNone\u001b[39;00m:\n",
      "\u001b[31mImportError\u001b[39m: \nA module that was compiled using NumPy 1.x cannot be run in\nNumPy 2.2.4 as it may crash. To support both 1.x and 2.x\nversions of NumPy, modules must be compiled with NumPy 2.0.\nSome module may need to rebuild instead e.g. with 'pybind11>=2.12'.\n\nIf you are a user of the module, the easiest solution will be to\ndowngrade to 'numpy<2' or try to upgrade the affected module.\nWe expect that some modules will need time to support NumPy 2.\n\n"
     ]
    },
    {
     "name": "stderr",
     "output_type": "stream",
     "text": [
      "\n",
      "A module that was compiled using NumPy 1.x cannot be run in\n",
      "NumPy 2.2.4 as it may crash. To support both 1.x and 2.x\n",
      "versions of NumPy, modules must be compiled with NumPy 2.0.\n",
      "Some module may need to rebuild instead e.g. with 'pybind11>=2.12'.\n",
      "\n",
      "If you are a user of the module, the easiest solution will be to\n",
      "downgrade to 'numpy<2' or try to upgrade the affected module.\n",
      "We expect that some modules will need time to support NumPy 2.\n",
      "\n",
      "Traceback (most recent call last):  File \"<frozen runpy>\", line 198, in _run_module_as_main\n",
      "  File \"<frozen runpy>\", line 88, in _run_code\n",
      "  File \"/home/codespace/.local/lib/python3.12/site-packages/ipykernel_launcher.py\", line 18, in <module>\n",
      "    app.launch_new_instance()\n",
      "  File \"/home/codespace/.local/lib/python3.12/site-packages/traitlets/config/application.py\", line 1075, in launch_instance\n",
      "    app.start()\n",
      "  File \"/home/codespace/.local/lib/python3.12/site-packages/ipykernel/kernelapp.py\", line 739, in start\n",
      "    self.io_loop.start()\n",
      "  File \"/home/codespace/.local/lib/python3.12/site-packages/tornado/platform/asyncio.py\", line 205, in start\n",
      "    self.asyncio_loop.run_forever()\n",
      "  File \"/home/codespace/anaconda3/lib/python3.12/asyncio/base_events.py\", line 641, in run_forever\n",
      "    self._run_once()\n",
      "  File \"/home/codespace/anaconda3/lib/python3.12/asyncio/base_events.py\", line 1986, in _run_once\n",
      "    handle._run()\n",
      "  File \"/home/codespace/anaconda3/lib/python3.12/asyncio/events.py\", line 88, in _run\n",
      "    self._context.run(self._callback, *self._args)\n",
      "  File \"/home/codespace/.local/lib/python3.12/site-packages/ipykernel/kernelbase.py\", line 545, in dispatch_queue\n",
      "    await self.process_one()\n",
      "  File \"/home/codespace/.local/lib/python3.12/site-packages/ipykernel/kernelbase.py\", line 534, in process_one\n",
      "    await dispatch(*args)\n",
      "  File \"/home/codespace/.local/lib/python3.12/site-packages/ipykernel/kernelbase.py\", line 437, in dispatch_shell\n",
      "    await result\n",
      "  File \"/home/codespace/.local/lib/python3.12/site-packages/ipykernel/ipkernel.py\", line 362, in execute_request\n",
      "    await super().execute_request(stream, ident, parent)\n",
      "  File \"/home/codespace/.local/lib/python3.12/site-packages/ipykernel/kernelbase.py\", line 778, in execute_request\n",
      "    reply_content = await reply_content\n",
      "  File \"/home/codespace/.local/lib/python3.12/site-packages/ipykernel/ipkernel.py\", line 449, in do_execute\n",
      "    res = shell.run_cell(\n",
      "  File \"/home/codespace/.local/lib/python3.12/site-packages/ipykernel/zmqshell.py\", line 549, in run_cell\n",
      "    return super().run_cell(*args, **kwargs)\n",
      "  File \"/home/codespace/.local/lib/python3.12/site-packages/IPython/core/interactiveshell.py\", line 3047, in run_cell\n",
      "    result = self._run_cell(\n",
      "  File \"/home/codespace/.local/lib/python3.12/site-packages/IPython/core/interactiveshell.py\", line 3102, in _run_cell\n",
      "    result = runner(coro)\n",
      "  File \"/home/codespace/.local/lib/python3.12/site-packages/IPython/core/async_helpers.py\", line 128, in _pseudo_sync_runner\n",
      "    coro.send(None)\n",
      "  File \"/home/codespace/.local/lib/python3.12/site-packages/IPython/core/interactiveshell.py\", line 3306, in run_cell_async\n",
      "    has_raised = await self.run_ast_nodes(code_ast.body, cell_name,\n",
      "  File \"/home/codespace/.local/lib/python3.12/site-packages/IPython/core/interactiveshell.py\", line 3489, in run_ast_nodes\n",
      "    if await self.run_code(code, result, async_=asy):\n",
      "  File \"/home/codespace/.local/lib/python3.12/site-packages/IPython/core/interactiveshell.py\", line 3549, in run_code\n",
      "    exec(code_obj, self.user_global_ns, self.user_ns)\n",
      "  File \"/tmp/ipykernel_24631/1375686775.py\", line 1, in <module>\n",
      "    import sklearn\n",
      "  File \"/home/codespace/.local/lib/python3.12/site-packages/sklearn/__init__.py\", line 73, in <module>\n",
      "    from .base import clone  # noqa: E402\n",
      "  File \"/home/codespace/.local/lib/python3.12/site-packages/sklearn/base.py\", line 19, in <module>\n",
      "    from .utils._estimator_html_repr import _HTMLDocumentationLinkMixin, estimator_html_repr\n",
      "  File \"/home/codespace/.local/lib/python3.12/site-packages/sklearn/utils/__init__.py\", line 15, in <module>\n",
      "    from ._chunking import gen_batches, gen_even_slices\n",
      "  File \"/home/codespace/.local/lib/python3.12/site-packages/sklearn/utils/_chunking.py\", line 11, in <module>\n",
      "    from ._param_validation import Interval, validate_params\n",
      "  File \"/home/codespace/.local/lib/python3.12/site-packages/sklearn/utils/_param_validation.py\", line 17, in <module>\n",
      "    from .validation import _is_arraylike_not_scalar\n",
      "  File \"/home/codespace/.local/lib/python3.12/site-packages/sklearn/utils/validation.py\", line 21, in <module>\n",
      "    from ..utils._array_api import _asarray_with_order, _is_numpy_namespace, get_namespace\n",
      "  File \"/home/codespace/.local/lib/python3.12/site-packages/sklearn/utils/_array_api.py\", line 17, in <module>\n",
      "    from .fixes import parse_version\n",
      "  File \"/home/codespace/.local/lib/python3.12/site-packages/sklearn/utils/fixes.py\", line 20, in <module>\n",
      "    import pandas as pd\n",
      "  File \"/home/codespace/.local/lib/python3.12/site-packages/pandas/__init__.py\", line 49, in <module>\n",
      "    from pandas.core.api import (\n",
      "  File \"/home/codespace/.local/lib/python3.12/site-packages/pandas/core/api.py\", line 9, in <module>\n",
      "    from pandas.core.dtypes.dtypes import (\n",
      "  File \"/home/codespace/.local/lib/python3.12/site-packages/pandas/core/dtypes/dtypes.py\", line 24, in <module>\n",
      "    from pandas._libs import (\n",
      "  File \"/home/codespace/anaconda3/lib/python3.12/site-packages/pyarrow/__init__.py\", line 65, in <module>\n",
      "    import pyarrow.lib as _lib\n"
     ]
    },
    {
     "ename": "ImportError",
     "evalue": "\nA module that was compiled using NumPy 1.x cannot be run in\nNumPy 2.2.4 as it may crash. To support both 1.x and 2.x\nversions of NumPy, modules must be compiled with NumPy 2.0.\nSome module may need to rebuild instead e.g. with 'pybind11>=2.12'.\n\nIf you are a user of the module, the easiest solution will be to\ndowngrade to 'numpy<2' or try to upgrade the affected module.\nWe expect that some modules will need time to support NumPy 2.\n\n",
     "output_type": "error",
     "traceback": [
      "\u001b[31m---------------------------------------------------------------------------\u001b[39m",
      "\u001b[31mImportError\u001b[39m                               Traceback (most recent call last)",
      "\u001b[36mFile \u001b[39m\u001b[32m~/.local/lib/python3.12/site-packages/numpy/core/_multiarray_umath.py:44\u001b[39m, in \u001b[36m__getattr__\u001b[39m\u001b[34m(attr_name)\u001b[39m\n\u001b[32m     39\u001b[39m     \u001b[38;5;66;03m# Also print the message (with traceback).  This is because old versions\u001b[39;00m\n\u001b[32m     40\u001b[39m     \u001b[38;5;66;03m# of NumPy unfortunately set up the import to replace (and hide) the\u001b[39;00m\n\u001b[32m     41\u001b[39m     \u001b[38;5;66;03m# error.  The traceback shouldn't be needed, but e.g. pytest plugins\u001b[39;00m\n\u001b[32m     42\u001b[39m     \u001b[38;5;66;03m# seem to swallow it and we should be failing anyway...\u001b[39;00m\n\u001b[32m     43\u001b[39m     sys.stderr.write(msg + tb_msg)\n\u001b[32m---> \u001b[39m\u001b[32m44\u001b[39m     \u001b[38;5;28;01mraise\u001b[39;00m \u001b[38;5;167;01mImportError\u001b[39;00m(msg)\n\u001b[32m     46\u001b[39m ret = \u001b[38;5;28mgetattr\u001b[39m(_multiarray_umath, attr_name, \u001b[38;5;28;01mNone\u001b[39;00m)\n\u001b[32m     47\u001b[39m \u001b[38;5;28;01mif\u001b[39;00m ret \u001b[38;5;129;01mis\u001b[39;00m \u001b[38;5;28;01mNone\u001b[39;00m:\n",
      "\u001b[31mImportError\u001b[39m: \nA module that was compiled using NumPy 1.x cannot be run in\nNumPy 2.2.4 as it may crash. To support both 1.x and 2.x\nversions of NumPy, modules must be compiled with NumPy 2.0.\nSome module may need to rebuild instead e.g. with 'pybind11>=2.12'.\n\nIf you are a user of the module, the easiest solution will be to\ndowngrade to 'numpy<2' or try to upgrade the affected module.\nWe expect that some modules will need time to support NumPy 2.\n\n"
     ]
    },
    {
     "name": "stderr",
     "output_type": "stream",
     "text": [
      "\n",
      "A module that was compiled using NumPy 1.x cannot be run in\n",
      "NumPy 2.2.4 as it may crash. To support both 1.x and 2.x\n",
      "versions of NumPy, modules must be compiled with NumPy 2.0.\n",
      "Some module may need to rebuild instead e.g. with 'pybind11>=2.12'.\n",
      "\n",
      "If you are a user of the module, the easiest solution will be to\n",
      "downgrade to 'numpy<2' or try to upgrade the affected module.\n",
      "We expect that some modules will need time to support NumPy 2.\n",
      "\n",
      "Traceback (most recent call last):  File \"<frozen runpy>\", line 198, in _run_module_as_main\n",
      "  File \"<frozen runpy>\", line 88, in _run_code\n",
      "  File \"/home/codespace/.local/lib/python3.12/site-packages/ipykernel_launcher.py\", line 18, in <module>\n",
      "    app.launch_new_instance()\n",
      "  File \"/home/codespace/.local/lib/python3.12/site-packages/traitlets/config/application.py\", line 1075, in launch_instance\n",
      "    app.start()\n",
      "  File \"/home/codespace/.local/lib/python3.12/site-packages/ipykernel/kernelapp.py\", line 739, in start\n",
      "    self.io_loop.start()\n",
      "  File \"/home/codespace/.local/lib/python3.12/site-packages/tornado/platform/asyncio.py\", line 205, in start\n",
      "    self.asyncio_loop.run_forever()\n",
      "  File \"/home/codespace/anaconda3/lib/python3.12/asyncio/base_events.py\", line 641, in run_forever\n",
      "    self._run_once()\n",
      "  File \"/home/codespace/anaconda3/lib/python3.12/asyncio/base_events.py\", line 1986, in _run_once\n",
      "    handle._run()\n",
      "  File \"/home/codespace/anaconda3/lib/python3.12/asyncio/events.py\", line 88, in _run\n",
      "    self._context.run(self._callback, *self._args)\n",
      "  File \"/home/codespace/.local/lib/python3.12/site-packages/ipykernel/kernelbase.py\", line 545, in dispatch_queue\n",
      "    await self.process_one()\n",
      "  File \"/home/codespace/.local/lib/python3.12/site-packages/ipykernel/kernelbase.py\", line 534, in process_one\n",
      "    await dispatch(*args)\n",
      "  File \"/home/codespace/.local/lib/python3.12/site-packages/ipykernel/kernelbase.py\", line 437, in dispatch_shell\n",
      "    await result\n",
      "  File \"/home/codespace/.local/lib/python3.12/site-packages/ipykernel/ipkernel.py\", line 362, in execute_request\n",
      "    await super().execute_request(stream, ident, parent)\n",
      "  File \"/home/codespace/.local/lib/python3.12/site-packages/ipykernel/kernelbase.py\", line 778, in execute_request\n",
      "    reply_content = await reply_content\n",
      "  File \"/home/codespace/.local/lib/python3.12/site-packages/ipykernel/ipkernel.py\", line 449, in do_execute\n",
      "    res = shell.run_cell(\n",
      "  File \"/home/codespace/.local/lib/python3.12/site-packages/ipykernel/zmqshell.py\", line 549, in run_cell\n",
      "    return super().run_cell(*args, **kwargs)\n",
      "  File \"/home/codespace/.local/lib/python3.12/site-packages/IPython/core/interactiveshell.py\", line 3047, in run_cell\n",
      "    result = self._run_cell(\n",
      "  File \"/home/codespace/.local/lib/python3.12/site-packages/IPython/core/interactiveshell.py\", line 3102, in _run_cell\n",
      "    result = runner(coro)\n",
      "  File \"/home/codespace/.local/lib/python3.12/site-packages/IPython/core/async_helpers.py\", line 128, in _pseudo_sync_runner\n",
      "    coro.send(None)\n",
      "  File \"/home/codespace/.local/lib/python3.12/site-packages/IPython/core/interactiveshell.py\", line 3306, in run_cell_async\n",
      "    has_raised = await self.run_ast_nodes(code_ast.body, cell_name,\n",
      "  File \"/home/codespace/.local/lib/python3.12/site-packages/IPython/core/interactiveshell.py\", line 3489, in run_ast_nodes\n",
      "    if await self.run_code(code, result, async_=asy):\n",
      "  File \"/home/codespace/.local/lib/python3.12/site-packages/IPython/core/interactiveshell.py\", line 3549, in run_code\n",
      "    exec(code_obj, self.user_global_ns, self.user_ns)\n",
      "  File \"/tmp/ipykernel_24631/1375686775.py\", line 1, in <module>\n",
      "    import sklearn\n",
      "  File \"/home/codespace/.local/lib/python3.12/site-packages/sklearn/__init__.py\", line 73, in <module>\n",
      "    from .base import clone  # noqa: E402\n",
      "  File \"/home/codespace/.local/lib/python3.12/site-packages/sklearn/base.py\", line 19, in <module>\n",
      "    from .utils._estimator_html_repr import _HTMLDocumentationLinkMixin, estimator_html_repr\n",
      "  File \"/home/codespace/.local/lib/python3.12/site-packages/sklearn/utils/__init__.py\", line 15, in <module>\n",
      "    from ._chunking import gen_batches, gen_even_slices\n",
      "  File \"/home/codespace/.local/lib/python3.12/site-packages/sklearn/utils/_chunking.py\", line 11, in <module>\n",
      "    from ._param_validation import Interval, validate_params\n",
      "  File \"/home/codespace/.local/lib/python3.12/site-packages/sklearn/utils/_param_validation.py\", line 17, in <module>\n",
      "    from .validation import _is_arraylike_not_scalar\n",
      "  File \"/home/codespace/.local/lib/python3.12/site-packages/sklearn/utils/validation.py\", line 21, in <module>\n",
      "    from ..utils._array_api import _asarray_with_order, _is_numpy_namespace, get_namespace\n",
      "  File \"/home/codespace/.local/lib/python3.12/site-packages/sklearn/utils/_array_api.py\", line 17, in <module>\n",
      "    from .fixes import parse_version\n",
      "  File \"/home/codespace/.local/lib/python3.12/site-packages/sklearn/utils/fixes.py\", line 20, in <module>\n",
      "    import pandas as pd\n",
      "  File \"/home/codespace/.local/lib/python3.12/site-packages/pandas/__init__.py\", line 49, in <module>\n",
      "    from pandas.core.api import (\n",
      "  File \"/home/codespace/.local/lib/python3.12/site-packages/pandas/core/api.py\", line 28, in <module>\n",
      "    from pandas.core.arrays import Categorical\n",
      "  File \"/home/codespace/.local/lib/python3.12/site-packages/pandas/core/arrays/__init__.py\", line 1, in <module>\n",
      "    from pandas.core.arrays.arrow import ArrowExtensionArray\n",
      "  File \"/home/codespace/.local/lib/python3.12/site-packages/pandas/core/arrays/arrow/__init__.py\", line 5, in <module>\n",
      "    from pandas.core.arrays.arrow.array import ArrowExtensionArray\n",
      "  File \"/home/codespace/.local/lib/python3.12/site-packages/pandas/core/arrays/arrow/array.py\", line 50, in <module>\n",
      "    from pandas.core import (\n",
      "  File \"/home/codespace/.local/lib/python3.12/site-packages/pandas/core/ops/__init__.py\", line 8, in <module>\n",
      "    from pandas.core.ops.array_ops import (\n",
      "  File \"/home/codespace/.local/lib/python3.12/site-packages/pandas/core/ops/array_ops.py\", line 56, in <module>\n",
      "    from pandas.core.computation import expressions\n",
      "  File \"/home/codespace/.local/lib/python3.12/site-packages/pandas/core/computation/expressions.py\", line 21, in <module>\n",
      "    from pandas.core.computation.check import NUMEXPR_INSTALLED\n",
      "  File \"/home/codespace/.local/lib/python3.12/site-packages/pandas/core/computation/check.py\", line 5, in <module>\n",
      "    ne = import_optional_dependency(\"numexpr\", errors=\"warn\")\n",
      "  File \"/home/codespace/.local/lib/python3.12/site-packages/pandas/compat/_optional.py\", line 135, in import_optional_dependency\n",
      "    module = importlib.import_module(name)\n",
      "  File \"/home/codespace/anaconda3/lib/python3.12/importlib/__init__.py\", line 90, in import_module\n",
      "    return _bootstrap._gcd_import(name[level:], package, level)\n",
      "  File \"/home/codespace/anaconda3/lib/python3.12/site-packages/numexpr/__init__.py\", line 24, in <module>\n",
      "    from numexpr.interpreter import MAX_THREADS, use_vml, __BLOCK_SIZE1__\n"
     ]
    },
    {
     "ename": "AttributeError",
     "evalue": "_ARRAY_API not found",
     "output_type": "error",
     "traceback": [
      "\u001b[31m---------------------------------------------------------------------------\u001b[39m",
      "\u001b[31mAttributeError\u001b[39m                            Traceback (most recent call last)",
      "\u001b[31mAttributeError\u001b[39m: _ARRAY_API not found"
     ]
    },
    {
     "name": "stderr",
     "output_type": "stream",
     "text": [
      "\n",
      "A module that was compiled using NumPy 1.x cannot be run in\n",
      "NumPy 2.2.4 as it may crash. To support both 1.x and 2.x\n",
      "versions of NumPy, modules must be compiled with NumPy 2.0.\n",
      "Some module may need to rebuild instead e.g. with 'pybind11>=2.12'.\n",
      "\n",
      "If you are a user of the module, the easiest solution will be to\n",
      "downgrade to 'numpy<2' or try to upgrade the affected module.\n",
      "We expect that some modules will need time to support NumPy 2.\n",
      "\n",
      "Traceback (most recent call last):  File \"<frozen runpy>\", line 198, in _run_module_as_main\n",
      "  File \"<frozen runpy>\", line 88, in _run_code\n",
      "  File \"/home/codespace/.local/lib/python3.12/site-packages/ipykernel_launcher.py\", line 18, in <module>\n",
      "    app.launch_new_instance()\n",
      "  File \"/home/codespace/.local/lib/python3.12/site-packages/traitlets/config/application.py\", line 1075, in launch_instance\n",
      "    app.start()\n",
      "  File \"/home/codespace/.local/lib/python3.12/site-packages/ipykernel/kernelapp.py\", line 739, in start\n",
      "    self.io_loop.start()\n",
      "  File \"/home/codespace/.local/lib/python3.12/site-packages/tornado/platform/asyncio.py\", line 205, in start\n",
      "    self.asyncio_loop.run_forever()\n",
      "  File \"/home/codespace/anaconda3/lib/python3.12/asyncio/base_events.py\", line 641, in run_forever\n",
      "    self._run_once()\n",
      "  File \"/home/codespace/anaconda3/lib/python3.12/asyncio/base_events.py\", line 1986, in _run_once\n",
      "    handle._run()\n",
      "  File \"/home/codespace/anaconda3/lib/python3.12/asyncio/events.py\", line 88, in _run\n",
      "    self._context.run(self._callback, *self._args)\n",
      "  File \"/home/codespace/.local/lib/python3.12/site-packages/ipykernel/kernelbase.py\", line 545, in dispatch_queue\n",
      "    await self.process_one()\n",
      "  File \"/home/codespace/.local/lib/python3.12/site-packages/ipykernel/kernelbase.py\", line 534, in process_one\n",
      "    await dispatch(*args)\n",
      "  File \"/home/codespace/.local/lib/python3.12/site-packages/ipykernel/kernelbase.py\", line 437, in dispatch_shell\n",
      "    await result\n",
      "  File \"/home/codespace/.local/lib/python3.12/site-packages/ipykernel/ipkernel.py\", line 362, in execute_request\n",
      "    await super().execute_request(stream, ident, parent)\n",
      "  File \"/home/codespace/.local/lib/python3.12/site-packages/ipykernel/kernelbase.py\", line 778, in execute_request\n",
      "    reply_content = await reply_content\n",
      "  File \"/home/codespace/.local/lib/python3.12/site-packages/ipykernel/ipkernel.py\", line 449, in do_execute\n",
      "    res = shell.run_cell(\n",
      "  File \"/home/codespace/.local/lib/python3.12/site-packages/ipykernel/zmqshell.py\", line 549, in run_cell\n",
      "    return super().run_cell(*args, **kwargs)\n",
      "  File \"/home/codespace/.local/lib/python3.12/site-packages/IPython/core/interactiveshell.py\", line 3047, in run_cell\n",
      "    result = self._run_cell(\n",
      "  File \"/home/codespace/.local/lib/python3.12/site-packages/IPython/core/interactiveshell.py\", line 3102, in _run_cell\n",
      "    result = runner(coro)\n",
      "  File \"/home/codespace/.local/lib/python3.12/site-packages/IPython/core/async_helpers.py\", line 128, in _pseudo_sync_runner\n",
      "    coro.send(None)\n",
      "  File \"/home/codespace/.local/lib/python3.12/site-packages/IPython/core/interactiveshell.py\", line 3306, in run_cell_async\n",
      "    has_raised = await self.run_ast_nodes(code_ast.body, cell_name,\n",
      "  File \"/home/codespace/.local/lib/python3.12/site-packages/IPython/core/interactiveshell.py\", line 3489, in run_ast_nodes\n",
      "    if await self.run_code(code, result, async_=asy):\n",
      "  File \"/home/codespace/.local/lib/python3.12/site-packages/IPython/core/interactiveshell.py\", line 3549, in run_code\n",
      "    exec(code_obj, self.user_global_ns, self.user_ns)\n",
      "  File \"/tmp/ipykernel_24631/1375686775.py\", line 1, in <module>\n",
      "    import sklearn\n",
      "  File \"/home/codespace/.local/lib/python3.12/site-packages/sklearn/__init__.py\", line 73, in <module>\n",
      "    from .base import clone  # noqa: E402\n",
      "  File \"/home/codespace/.local/lib/python3.12/site-packages/sklearn/base.py\", line 19, in <module>\n",
      "    from .utils._estimator_html_repr import _HTMLDocumentationLinkMixin, estimator_html_repr\n",
      "  File \"/home/codespace/.local/lib/python3.12/site-packages/sklearn/utils/__init__.py\", line 15, in <module>\n",
      "    from ._chunking import gen_batches, gen_even_slices\n",
      "  File \"/home/codespace/.local/lib/python3.12/site-packages/sklearn/utils/_chunking.py\", line 11, in <module>\n",
      "    from ._param_validation import Interval, validate_params\n",
      "  File \"/home/codespace/.local/lib/python3.12/site-packages/sklearn/utils/_param_validation.py\", line 17, in <module>\n",
      "    from .validation import _is_arraylike_not_scalar\n",
      "  File \"/home/codespace/.local/lib/python3.12/site-packages/sklearn/utils/validation.py\", line 21, in <module>\n",
      "    from ..utils._array_api import _asarray_with_order, _is_numpy_namespace, get_namespace\n",
      "  File \"/home/codespace/.local/lib/python3.12/site-packages/sklearn/utils/_array_api.py\", line 17, in <module>\n",
      "    from .fixes import parse_version\n",
      "  File \"/home/codespace/.local/lib/python3.12/site-packages/sklearn/utils/fixes.py\", line 20, in <module>\n",
      "    import pandas as pd\n",
      "  File \"/home/codespace/.local/lib/python3.12/site-packages/pandas/__init__.py\", line 49, in <module>\n",
      "    from pandas.core.api import (\n",
      "  File \"/home/codespace/.local/lib/python3.12/site-packages/pandas/core/api.py\", line 28, in <module>\n",
      "    from pandas.core.arrays import Categorical\n",
      "  File \"/home/codespace/.local/lib/python3.12/site-packages/pandas/core/arrays/__init__.py\", line 1, in <module>\n",
      "    from pandas.core.arrays.arrow import ArrowExtensionArray\n",
      "  File \"/home/codespace/.local/lib/python3.12/site-packages/pandas/core/arrays/arrow/__init__.py\", line 5, in <module>\n",
      "    from pandas.core.arrays.arrow.array import ArrowExtensionArray\n",
      "  File \"/home/codespace/.local/lib/python3.12/site-packages/pandas/core/arrays/arrow/array.py\", line 64, in <module>\n",
      "    from pandas.core.arrays.masked import BaseMaskedArray\n",
      "  File \"/home/codespace/.local/lib/python3.12/site-packages/pandas/core/arrays/masked.py\", line 60, in <module>\n",
      "    from pandas.core import (\n",
      "  File \"/home/codespace/.local/lib/python3.12/site-packages/pandas/core/nanops.py\", line 52, in <module>\n",
      "    bn = import_optional_dependency(\"bottleneck\", errors=\"warn\")\n",
      "  File \"/home/codespace/.local/lib/python3.12/site-packages/pandas/compat/_optional.py\", line 135, in import_optional_dependency\n",
      "    module = importlib.import_module(name)\n",
      "  File \"/home/codespace/anaconda3/lib/python3.12/importlib/__init__.py\", line 90, in import_module\n",
      "    return _bootstrap._gcd_import(name[level:], package, level)\n",
      "  File \"/home/codespace/anaconda3/lib/python3.12/site-packages/bottleneck/__init__.py\", line 7, in <module>\n",
      "    from .move import (move_argmax, move_argmin, move_max, move_mean, move_median,\n"
     ]
    },
    {
     "ename": "ImportError",
     "evalue": "\nA module that was compiled using NumPy 1.x cannot be run in\nNumPy 2.2.4 as it may crash. To support both 1.x and 2.x\nversions of NumPy, modules must be compiled with NumPy 2.0.\nSome module may need to rebuild instead e.g. with 'pybind11>=2.12'.\n\nIf you are a user of the module, the easiest solution will be to\ndowngrade to 'numpy<2' or try to upgrade the affected module.\nWe expect that some modules will need time to support NumPy 2.\n\n",
     "output_type": "error",
     "traceback": [
      "\u001b[31m---------------------------------------------------------------------------\u001b[39m",
      "\u001b[31mImportError\u001b[39m                               Traceback (most recent call last)",
      "\u001b[36mFile \u001b[39m\u001b[32m~/.local/lib/python3.12/site-packages/numpy/core/_multiarray_umath.py:44\u001b[39m, in \u001b[36m__getattr__\u001b[39m\u001b[34m(attr_name)\u001b[39m\n\u001b[32m     39\u001b[39m     \u001b[38;5;66;03m# Also print the message (with traceback).  This is because old versions\u001b[39;00m\n\u001b[32m     40\u001b[39m     \u001b[38;5;66;03m# of NumPy unfortunately set up the import to replace (and hide) the\u001b[39;00m\n\u001b[32m     41\u001b[39m     \u001b[38;5;66;03m# error.  The traceback shouldn't be needed, but e.g. pytest plugins\u001b[39;00m\n\u001b[32m     42\u001b[39m     \u001b[38;5;66;03m# seem to swallow it and we should be failing anyway...\u001b[39;00m\n\u001b[32m     43\u001b[39m     sys.stderr.write(msg + tb_msg)\n\u001b[32m---> \u001b[39m\u001b[32m44\u001b[39m     \u001b[38;5;28;01mraise\u001b[39;00m \u001b[38;5;167;01mImportError\u001b[39;00m(msg)\n\u001b[32m     46\u001b[39m ret = \u001b[38;5;28mgetattr\u001b[39m(_multiarray_umath, attr_name, \u001b[38;5;28;01mNone\u001b[39;00m)\n\u001b[32m     47\u001b[39m \u001b[38;5;28;01mif\u001b[39;00m ret \u001b[38;5;129;01mis\u001b[39;00m \u001b[38;5;28;01mNone\u001b[39;00m:\n",
      "\u001b[31mImportError\u001b[39m: \nA module that was compiled using NumPy 1.x cannot be run in\nNumPy 2.2.4 as it may crash. To support both 1.x and 2.x\nversions of NumPy, modules must be compiled with NumPy 2.0.\nSome module may need to rebuild instead e.g. with 'pybind11>=2.12'.\n\nIf you are a user of the module, the easiest solution will be to\ndowngrade to 'numpy<2' or try to upgrade the affected module.\nWe expect that some modules will need time to support NumPy 2.\n\n"
     ]
    }
   ],
   "source": [
    "import sklearn\n",
    "import pandas as pd"
   ]
  },
  {
   "cell_type": "code",
   "execution_count": 2,
   "id": "6c9bcf09-9ba8-457b-83fd-2f30983a983e",
   "metadata": {},
   "outputs": [
    {
     "data": {
      "text/plain": [
       "'2.2.3'"
      ]
     },
     "execution_count": 2,
     "metadata": {},
     "output_type": "execute_result"
    }
   ],
   "source": [
    "pd.__version__"
   ]
  },
  {
   "cell_type": "code",
   "execution_count": null,
   "id": "9acb1ae3-5ced-4c08-a9c4-9b0dab482a8f",
   "metadata": {},
   "outputs": [],
   "source": []
  }
 ],
 "metadata": {
  "kernelspec": {
   "display_name": "Python 3 (ipykernel)",
   "language": "python",
   "name": "python3"
  },
  "language_info": {
   "codemirror_mode": {
    "name": "ipython",
    "version": 3
   },
   "file_extension": ".py",
   "mimetype": "text/x-python",
   "name": "python",
   "nbconvert_exporter": "python",
   "pygments_lexer": "ipython3",
   "version": "3.12.7"
  }
 },
 "nbformat": 4,
 "nbformat_minor": 5
}
